{"cells":[{"cell_type":"code","execution_count":3,"metadata":{},"outputs":[],"source":["import pandas as pd\n","import numpy as np\n","from numpy import loadtxt\n","from tensorflow.keras.models import Sequential\n","from tensorflow.keras.layers import Dense\n","from tensorflow.keras.utils import to_categorical, plot_model\n","\n","df = pd.read_csv('./test.csv', on_bad_lines='skip')\n"]},{"cell_type":"code","execution_count":4,"metadata":{},"outputs":[{"name":"stdout","output_type":"stream","text":["[[1.]\n"," [1.]\n"," [1.]\n"," ...\n"," [1.]\n"," [1.]\n"," [1.]]\n"]}],"source":["X = df.iloc[:, 1:]\n","Y = to_categorical(df.iloc[:, 0])\n","\n","print(Y)\n"]},{"cell_type":"code","execution_count":5,"metadata":{},"outputs":[],"source":["modal = Sequential()\n","modal.add(Dense(12, input_shape=(784,), activation='relu'))\n","modal.add(Dense(8, activation='relu'))\n","modal.add(Dense(10, activation='sigmoid'))\n"]},{"cell_type":"code","execution_count":7,"metadata":{},"outputs":[{"name":"stdout","output_type":"stream","text":["Epoch 1/150\n"]},{"ename":"ValueError","evalue":"in user code:\n\n    File \"c:\\Users\\Нурдаулет\\AppData\\Local\\Programs\\Python\\Python310\\lib\\site-packages\\keras\\engine\\training.py\", line 1160, in train_function  *\n        return step_function(self, iterator)\n    File \"c:\\Users\\Нурдаулет\\AppData\\Local\\Programs\\Python\\Python310\\lib\\site-packages\\keras\\engine\\training.py\", line 1146, in step_function  **\n        outputs = model.distribute_strategy.run(run_step, args=(data,))\n    File \"c:\\Users\\Нурдаулет\\AppData\\Local\\Programs\\Python\\Python310\\lib\\site-packages\\keras\\engine\\training.py\", line 1135, in run_step  **\n        outputs = model.train_step(data)\n    File \"c:\\Users\\Нурдаулет\\AppData\\Local\\Programs\\Python\\Python310\\lib\\site-packages\\keras\\engine\\training.py\", line 993, in train_step\n        y_pred = self(x, training=True)\n    File \"c:\\Users\\Нурдаулет\\AppData\\Local\\Programs\\Python\\Python310\\lib\\site-packages\\keras\\utils\\traceback_utils.py\", line 70, in error_handler\n        raise e.with_traceback(filtered_tb) from None\n    File \"c:\\Users\\Нурдаулет\\AppData\\Local\\Programs\\Python\\Python310\\lib\\site-packages\\keras\\engine\\input_spec.py\", line 295, in assert_input_compatibility\n        raise ValueError(\n\n    ValueError: Input 0 of layer \"sequential\" is incompatible with the layer: expected shape=(None, 784), found shape=(10, 783)\n","output_type":"error","traceback":["\u001b[1;31m---------------------------------------------------------------------------\u001b[0m","\u001b[1;31mValueError\u001b[0m                                Traceback (most recent call last)","Cell \u001b[1;32mIn [7], line 2\u001b[0m\n\u001b[0;32m      1\u001b[0m modal\u001b[39m.\u001b[39mcompile(loss\u001b[39m=\u001b[39m\u001b[39m'\u001b[39m\u001b[39mbinary_crossentropy\u001b[39m\u001b[39m'\u001b[39m, optimizer\u001b[39m=\u001b[39m\u001b[39m'\u001b[39m\u001b[39madam\u001b[39m\u001b[39m'\u001b[39m, metrics\u001b[39m=\u001b[39m[\u001b[39m'\u001b[39m\u001b[39maccuracy\u001b[39m\u001b[39m'\u001b[39m])\n\u001b[1;32m----> 2\u001b[0m modal\u001b[39m.\u001b[39mfit(X, Y, epochs\u001b[39m=\u001b[39m\u001b[39m150\u001b[39m, batch_size\u001b[39m=\u001b[39m\u001b[39m10\u001b[39m)\n","File \u001b[1;32mc:\\Users\\Нурдаулет\\AppData\\Local\\Programs\\Python\\Python310\\lib\\site-packages\\keras\\utils\\traceback_utils.py:70\u001b[0m, in \u001b[0;36mfilter_traceback.<locals>.error_handler\u001b[1;34m(*args, **kwargs)\u001b[0m\n\u001b[0;32m     67\u001b[0m     filtered_tb \u001b[39m=\u001b[39m _process_traceback_frames(e\u001b[39m.\u001b[39m__traceback__)\n\u001b[0;32m     68\u001b[0m     \u001b[39m# To get the full stack trace, call:\u001b[39;00m\n\u001b[0;32m     69\u001b[0m     \u001b[39m# `tf.debugging.disable_traceback_filtering()`\u001b[39;00m\n\u001b[1;32m---> 70\u001b[0m     \u001b[39mraise\u001b[39;00m e\u001b[39m.\u001b[39mwith_traceback(filtered_tb) \u001b[39mfrom\u001b[39;00m \u001b[39mNone\u001b[39m\n\u001b[0;32m     71\u001b[0m \u001b[39mfinally\u001b[39;00m:\n\u001b[0;32m     72\u001b[0m     \u001b[39mdel\u001b[39;00m filtered_tb\n","File \u001b[1;32mC:\\Users\\17E9~1\\AppData\\Local\\Temp\\__autograph_generated_file627e1imp.py:15\u001b[0m, in \u001b[0;36mouter_factory.<locals>.inner_factory.<locals>.tf__train_function\u001b[1;34m(iterator)\u001b[0m\n\u001b[0;32m     13\u001b[0m \u001b[39mtry\u001b[39;00m:\n\u001b[0;32m     14\u001b[0m     do_return \u001b[39m=\u001b[39m \u001b[39mTrue\u001b[39;00m\n\u001b[1;32m---> 15\u001b[0m     retval_ \u001b[39m=\u001b[39m ag__\u001b[39m.\u001b[39mconverted_call(ag__\u001b[39m.\u001b[39mld(step_function), (ag__\u001b[39m.\u001b[39mld(\u001b[39mself\u001b[39m), ag__\u001b[39m.\u001b[39mld(iterator)), \u001b[39mNone\u001b[39;00m, fscope)\n\u001b[0;32m     16\u001b[0m \u001b[39mexcept\u001b[39;00m:\n\u001b[0;32m     17\u001b[0m     do_return \u001b[39m=\u001b[39m \u001b[39mFalse\u001b[39;00m\n","\u001b[1;31mValueError\u001b[0m: in user code:\n\n    File \"c:\\Users\\Нурдаулет\\AppData\\Local\\Programs\\Python\\Python310\\lib\\site-packages\\keras\\engine\\training.py\", line 1160, in train_function  *\n        return step_function(self, iterator)\n    File \"c:\\Users\\Нурдаулет\\AppData\\Local\\Programs\\Python\\Python310\\lib\\site-packages\\keras\\engine\\training.py\", line 1146, in step_function  **\n        outputs = model.distribute_strategy.run(run_step, args=(data,))\n    File \"c:\\Users\\Нурдаулет\\AppData\\Local\\Programs\\Python\\Python310\\lib\\site-packages\\keras\\engine\\training.py\", line 1135, in run_step  **\n        outputs = model.train_step(data)\n    File \"c:\\Users\\Нурдаулет\\AppData\\Local\\Programs\\Python\\Python310\\lib\\site-packages\\keras\\engine\\training.py\", line 993, in train_step\n        y_pred = self(x, training=True)\n    File \"c:\\Users\\Нурдаулет\\AppData\\Local\\Programs\\Python\\Python310\\lib\\site-packages\\keras\\utils\\traceback_utils.py\", line 70, in error_handler\n        raise e.with_traceback(filtered_tb) from None\n    File \"c:\\Users\\Нурдаулет\\AppData\\Local\\Programs\\Python\\Python310\\lib\\site-packages\\keras\\engine\\input_spec.py\", line 295, in assert_input_compatibility\n        raise ValueError(\n\n    ValueError: Input 0 of layer \"sequential\" is incompatible with the layer: expected shape=(None, 784), found shape=(10, 783)\n"]}],"source":["modal.compile(loss='binary_crossentropy', optimizer='adam', metrics=['accuracy'])\n","modal.fit(X, Y, epochs=150, batch_size=10)"]}],"metadata":{"kernelspec":{"display_name":"Python 3.10.4 64-bit","language":"python","name":"python3"},"language_info":{"codemirror_mode":{"name":"ipython","version":3},"file_extension":".py","mimetype":"text/x-python","name":"python","nbconvert_exporter":"python","pygments_lexer":"ipython3","version":"3.10.4"},"orig_nbformat":4,"vscode":{"interpreter":{"hash":"736d40e8a52ea3dbb66361c7c47071f66b4aaa68a21e744a172cabe44f437706"}}},"nbformat":4,"nbformat_minor":2}
